Workbook

Sheet Summary
A1: 指标 | B1: 值
A2: 总题数 | B2: =COUNTA('QA Review'!A:A)-1 -> 100
A3: 自动正确数 | B3: =COUNTIF('QA Review'!I:I,"正确") -> 97
A4: 自动部分正确数 | B4: =COUNTIF('QA Review'!I:I,"部分正确") -> 0
A5: 自动错误数 | B5: =COUNTIF('QA Review'!I:I,"错误") -> 1
A6: 自动请求失败数 | B6: =COUNTIF('QA Review'!I:I,"请求失败") -> 1
A7: 自动加权准确率 | B7: =SUM('QA Review'!J:J)/B2 -> 1.96
A9: 人工正确数 | B9: =COUNTIF('QA Review'!N:N,"正确") -> 0
A10: 人工部分正确数 | B10: =COUNTIF('QA Review'!N:N,"部分正确") -> 0
A11: 人工错误数 | B11: =COUNTIF('QA Review'!N:N,"错误") -> 0
A12: 人工严格准确率 | B12: =B9/B2 -> 0
A13: 人工加权准确率 | B13: =SUM('QA Review'!O:O)/B2 -> 0
A14: 知识库命中率 | B14: =COUNTIF('QA Review'!H:H,"是")/B2 -> 0
A16: 人工复核建议：先筛选自动判定=错误/请求失败，再逐条补充人工复核结果、人工判定说明和知识库命中情况。

Sheet QA Review
A1: 用例ID | B1: 问题 | C1: 问题类型 | D1: 标准答案_关键点 | E1: 关联知识文件 | F1: memoryId | G1: 系统回答 | H1: 是否命中知识库 | I1: 自动判定 | J1: 自动得分 | K1: 命中关键点数 | L1: 关键点总数 | M1: 命中关键词 | N1: 人工复核结果 | O1: 人工复核得分 | P1: 人工判定说明 | Q1: 备注
A2: QA-001 | B2: 头痛应该挂什么科？ | C2: 科室推荐 | D2: 神经内科；结合症状判断 | E2: 科室信息.md | F2: 900001 | G2: 头痛通常建议首先挂 **神经内科**。 如果伴有以下情况，也可考虑相应科室： - 头部外伤史 → **神经外科** - 视力问题或眼痛 → **眼科** - 鼻塞、流脓涕、面部胀痛 → **耳鼻喉科** - 血压明显升高 → **心内科** 初次不明原因的头痛，首选神经内科就诊，医生会根据情况决定是否需要做进一步检查（如头颅CT、MRI等）。 需要我帮您预约神经内科的号吗？😊 | I2: 正确 | J2: 1 | K2: 1 | L2: 2 | M2: 神经内科 | O2: =IF(N2="正确",1,IF(N2="部分正确",0.5,IF(N2="错误",0,"")))
A3: QA-002 | B3: 头晕一般建议看什么科？ | C3: 科室推荐 | D3: 神经内科；必要时进一步分诊 | E3: 科室信息.md | F3: 900002 | G3: 头晕通常建议根据具体症状选择科室： - **神经内科**：适合伴有头痛、肢体无力、言语不清等情况，排查脑供血不足、脑卒中等。 - **耳鼻喉科**：如果头晕像“天旋地转”，伴随耳鸣、恶心、听力变化，可能是内耳问题（如耳石症、梅尼埃病）。 - **心内科**：若与心慌、胸闷、血压异常相关，需考虑心血管原因。 - **老年医学科或全科**：老年人不明原因反复头晕，可先看全科进行综合评估。 ⚠️ 如果头晕严重、突发或持续不缓解，建议尽早就医检查。 需要我帮您预约挂号吗？😊 | I3: 正确 | J3: 1 | K3: 1 | L3: 2 | M3: 神经内科 | O3: =IF(N3="正确",1,IF(N3="部分正确",0.5,IF(N3="错误",0,"")))
A4: QA-003 | B4: 发烧应该挂什么科？ | C4: 科室推荐 | D4: 内科或发热门诊；视医院设置而定 | E4: 科室信息.md | F4: 900003 | G4: 发烧一般建议挂 **发热门诊** 或 **感染内科**。 - 如果伴有咳嗽、喉咙痛、流鼻涕等呼吸道症状，可挂 **呼吸内科**； - 如果是儿童发烧，请挂 **儿科**； - 若发烧持续不退、原因不明，或伴有皮疹、关节痛等其他症状，也可考虑 **内科综合门诊** 或由医生进一步分诊。 ⚠️ 温馨提示：如果体温超过38.5℃、精神状态差、出现抽搐、呼吸急促等情况，建议尽快就医。 需要我帮您查询号源或预约挂号吗？请告诉我就诊人姓名、身份证号、希望就诊的日期和时间段（上午/下午）即可。😊 | I4: 正确 | J4: 1 | K4: 0 | L4: 2 | O4: =IF(N4="正确",1,IF(N4="部分正确",0.5,IF(N4="错误",0,"")))
A5: QA-004 | B5: 咳嗽咳痰应该挂什么科？ | C5: 科室推荐 | D5: 呼吸内科 | E5: 科室信息.md | F5: 900004 | G5: 您好！咳嗽咳痰通常建议首先挂 **呼吸内科**。 如果伴有以下情况，也可考虑其他科室： - 发热、咽痛明显 → 可考虑 **感染内科** - 咳血、长期吸烟史、体重下降 → 建议尽快至 **呼吸内科** 或 **胸外科** 排查 - 儿童患者 → 可挂 **儿科呼吸专科** 如症状持续超过2周、加重或伴有呼吸困难，请及时线下就诊。需要我帮您查询呼吸内科的号源或预约挂号吗？😊 | I5: 正确 | J5: 1 | K5: 1 | L5: 1 | M5: 呼吸内科 | O5: =IF(N5="正确",1,IF(N5="部分正确",0.5,IF(N5="错误",0,"")))
A6: QA-005 | B6: 肚子疼一般挂什么科？ | C6: 科室推荐 | D6: 消化内科；急性剧痛需急诊 | E6: 科室信息.md | F6: 900005 | G6: 肚子疼通常建议先挂**消化内科**。如果疼痛剧烈、突发或伴有以下情况，也可能需要考虑其他科室： - 女性下腹痛明显 ➜ **妇科** - 伴有发热、黄疸、呕吐 ➜ **肝胆外科** 或 **普外科** - 儿童腹痛 ➜ **儿科** - 怀疑阑尾炎、肠梗阻等急症 ➜ **急诊科** 如果您不确定具体原因，可以先到**消化内科**就诊，医生会根据症状判断是否需要转诊或进一步检查。必要时请尽快线下就医，以免延误病情。🩺 | I6: 正确 | J6: 1 | K6: 1 | L6: 2 | M6: 消化内科 | O6: =IF(N6="正确",1,IF(N6="部分正确",0.5,IF(N6="错误",0,"")))
A7: QA-006 | B7: 胸闷胸痛应该先看哪个科？ | C7: 科室推荐 | D7: 心内科；严重情况建议急诊 | E7: 科室信息.md | F7: 900006 | G7: 您好！胸闷、胸痛可能是多种原因引起的，常见原因包括心脏、肺部、消化系统或肌肉骨骼等问题。为了明确病因，建议您**首先就诊心内科**，排查是否存在心脏相关疾病（如心绞痛、心肌缺血等），这是最需要优先排除的严重情况。 如果心内科检查后未发现明显异常，医生可能会根据您的具体症状，建议您进一步就诊： - **呼吸内科**（如伴有咳嗽、气短） - **消化内科**（如伴有反酸、烧心） - **胸外科** 或 **骨科**（如疼痛与体位、按压有关） ⚠️ 如果胸痛剧烈、持续不缓解、伴随大汗、呼吸困难等症状，请**立即前往急诊科就诊**！ 需要我帮您预约心内科的号吗？ | I7: 正确 | J7: 1 | K7: 1 | L7: 2 | M7: 心内科 | O7: =IF(N7="正确",1,IF(N7="部分正确",0.5,IF(N7="错误",0,"")))
A8: QA-007 | B8: 皮肤过敏应该挂什么科？ | C8: 科室推荐 | D8: 皮肤科 | E8: 科室信息.md | F8: 900007 | G8: 皮肤过敏建议挂 **皮肤科**。 如果您出现红斑、瘙痒、皮疹、肿胀等皮肤症状，皮肤科医生可以帮您明确过敏原并给予针对性治疗。若症状严重（如呼吸困难、面部明显肿胀等），请立即前往急诊科就诊。 需要我帮您预约皮肤科的号源吗？😊 | I8: 正确 | J8: 1 | K8: 1 | L8: 1 | M8: 皮肤科 | O8: =IF(N8="正确",1,IF(N8="部分正确",0.5,IF(N8="错误",0,"")))
A9: QA-008 | B9: 牙疼应该挂什么科？ | C9: 科室推荐 | D9: 口腔科 | E9: 科室信息.md | F9: 900008 | G9: 牙疼建议您挂 **口腔科**。 如果您疼痛剧烈、伴有肿胀、发烧，或者张口困难等情况，建议尽快就诊。北京协和医院口腔科可以处理牙痛、牙龈炎、牙周病、智齿发炎等多种口腔问题。 需要我帮您查询近期是否有号源或预约挂号吗？🦷 | I9: 正确 | J9: 1 | K9: 1 | L9: 1 | M9: 口腔科 | O9: =IF(N9="正确",1,IF(N9="部分正确",0.5,IF(N9="错误",0,"")))
A10: QA-009 | B10: 眼睛不舒服应该挂什么科？ | C10: 科室推荐 | D10: 眼科 | E10: 科室信息.md | F10: 900009 | G10: 眼睛不舒服建议挂 **眼科** 👁️。 常见的眼部不适，比如： - 眼干、眼涩、异物感 - 视力模糊、视物重影 - 眼红、流泪、分泌物增多 - 眼痛、畏光、闪光感等 都属于眼科的诊疗范围。如果症状持续或加重，建议尽早就医检查，以免延误治疗。 需要我帮您预约眼科的号源吗？ | I10: 正确 | J10: 1 | K10: 1 | L10: 1 | M10: 眼科 | O10: =IF(N10="正确",1,IF(N10="部分正确",0.5,IF(N10="错误",0,"")))
A11: QA-010 | B11: 耳鸣应该挂什么科？ | C11: 科室推荐 | D11: 耳鼻喉科 | E11: 科室信息.md | F11: 900010 | G11: 耳鸣通常建议挂 **耳鼻喉科（也称五官科）**。 耳鼻喉科医生可以对耳鸣的原因进行初步评估，比如是否与听力下降、耳部感染、耳垢堵塞、噪音暴露或内耳问题等相关。 如果耳鸣伴随以下情况，也建议及时就诊： - 单侧耳鸣 - 突然发生的严重耳鸣 - 伴有头晕、听力骤降或头痛 - 耳鸣持续时间较长（超过一周）且影响生活 需要我帮您查询北京协和医院耳鼻喉科的号源或预约挂号吗？👂 | I11: 正确 | J11: 1 | K11: 1 | L11: 1 | M11: 耳鼻喉科 | O11: =IF(N11="正确",1,IF(N11="部分正确",0.5,IF(N11="错误",0,"")))
A12: QA-011 | B12: 孩子发烧应该挂什么科？ | C12: 科室推荐 | D12: 儿科；严重情况急诊 | E12: 科室信息.md | F12: 900011 | G12: 您好！孩子发烧通常建议挂 **儿科**。如果体温持续高热（如超过39℃）、伴有皮疹、抽搐、精神差、呼吸急促或其他明显不适，建议尽快就诊。 在北京协和医院，您可以预约 **儿科普通号** 或 **儿科发热门诊**（如有开设）。是否需要我帮您查询近期的号源情况或协助预约？😊 | I12: 正确 | J12: 1 | K12: 1 | L12: 2 | M12: 儿科 | O12: =IF(N12="正确",1,IF(N12="部分正确",0.5,IF(N12="错误",0,"")))
A13: QA-012 | B13: 老人头晕头痛应该看什么科？ | C13: 科室推荐 | D13: 神经内科；结合基础病判断 | E13: 科室信息.md | F13: 900012 | G13: 老人出现头晕头痛，建议首先就诊 **神经内科**。这类症状可能与脑供血不足、高血压、脑血管疾病、颈椎病或其他神经系统问题有关。 如果协和医院神经内科号源紧张，也可以先到 **老年医学科** 或 **全科医学科（普通内科）** 初步评估，医生会根据情况决定是否需要转诊或进一步检查（如头颅CT、MRI、颈动脉超声等）。 ⚠️ 如果头晕头痛突然加重，伴有以下任一情况，请立即前往急诊： - 意识模糊、言语不清 - 一侧肢体无力或麻木 - 视力突然下降 - 剧烈呕吐或行走不稳 需要我帮您查询神经内科近期的号源或预约挂号吗？ | I13: 正确 | J13: 1 | K13: 1 | L13: 2 | M13: 神经内科 | O13: =IF(N13="正确",1,IF(N13="部分正确",0.5,IF(N13="错误",0,"")))
A14: QA-013 | B14: 胃不舒服挂什么科？ | C14: 科室推荐 | D14: 消化内科 | E14: 科室信息.md | F14: 900013 | G14: 您好！胃不舒服通常建议挂 **消化内科**。 常见的胃部不适症状（如胃痛、反酸、腹胀、恶心等）大多属于消化系统问题，消化内科医生会根据您的具体情况进行问诊，必要时安排胃镜、幽门螺杆菌检测或其他检查。 如果您还不确定具体科室，也可以先到医院的“分诊台”或通过协和医院官方App/小程序进行智能分诊。 需要我帮您预约消化内科的号吗？😊 | I14: 正确 | J14: 1 | K14: 1 | L14: 1 | M14: 消化内科 | O14: =IF(N14="正确",1,IF(N14="部分正确",0.5,IF(N14="错误",0,"")))
A15: QA-014 | B15: 失眠应该挂什么科？ | C15: 科室推荐 | D15: 神经内科或心理相关门诊 | E15: 科室信息.md | F15: 900014 | G15: 您好！失眠通常建议挂 **神经内科** 或 **心理科（精神科）**，具体可根据您的情况选择： - 如果失眠伴随焦虑、情绪低落、压力大等心理因素，建议挂 **心理科/精神科**； - 如果失眠伴随头痛、头晕、肢体麻木或其他神经系统症状，建议挂 **神经内科**； - 对于长期顽固性失眠，也可以考虑 **睡眠专科门诊**（部分医院设有专门的睡眠障碍门诊）。 在北京协和医院，您可以先选择 **神经内科** 或 **心理医学科** 进行初诊，医生会根据情况决定是否需要进一步检查或转诊。 如需帮您预约挂号，请告诉我： - 您希望就诊的科室（神经内科 / 心理科） - 就诊日期和时间段（上午 / 下午） - 是否有指定医生 我可以帮您查询号源并预约 😊 | I15: 正确 | J15: 1 | K15: 0 | L15: 1 | O15: =IF(N15="正确",1,IF(N15="部分正确",0.5,IF(N15="错误",0,"")))
A16: QA-015 | B16: 腰腿疼应该挂什么科？ | C16: 科室推荐 | D16: 骨科；必要时康复科 | E16: 科室信息.md | F16: 900015 | G16: 您好！腰腿疼通常建议首先挂 **骨科** 或 **脊柱外科**。如果医院分科较细，也可以考虑以下科室： - **骨科/脊柱外科**：排查腰椎间盘突出、椎管狭窄、脊柱退行性病变等问题； - **康复医学科**：适合慢性疼痛或术后康复； - **疼痛科**：若以疼痛为主要症状且原因不明确； - **神经内科**：如伴随下肢麻木、无力等神经症状。 在协和医院，多数腰腿痛患者首诊会选择 **骨科**。如果您方便提供更详细的症状（比如疼痛位置、是否放射至腿部、有无外伤史等），我可以帮您更精准地推荐。 需要我帮您查询相关科室的号源或预约挂号吗？ | I16: 正确 | J16: 1 | K16: 1 | L16: 2 | M16: 骨科 | O16: =IF(N16="正确",1,IF(N16="部分正确",0.5,IF(N16="错误",0,"")))
A17: QA-016 | B17: 医院地址在哪里？ | C17: 医院信息 | D17: 医院地址；交通方式 | E17: 医院信息.md | F17: 900016 | G17: 您好！我是“硅谷小智”，北京协和医院的智能客服，很高兴为您服务！😊 北京协和医院有两个院区，地址如下： - **东单院区**：北京市东城区帅府园一号（邮编：100730） - **西单院区**：北京市西城区大木仓胡同41号（邮编：100032） 🏥 **门诊开放时间**：工作日 8:00 – 17:30 🚑 **急诊**：24小时开放 📞 **服务热线**： - 东单院区：010-69151188 - 西单院区：010-69158100 如需预约挂号、查询科室或医生信息，也可以告诉我，我会尽力协助您！ | I17: 正确 | J17: 1 | K17: 0 | L17: 2 | O17: =IF(N17="正确",1,IF(N17="部分正确",0.5,IF(N17="错误",0,"")))
A18: QA-017 | B18: 医院门诊几点开始？ | C18: 医院信息 | D18: 门诊开始时间；上午时段 | E18: 医院信息.md | F18: 900017 | G18: 北京协和医院门诊通常在**上午8:00**开始，下午门诊一般从**13:30**开始（部分科室可能略有不同）。建议您提前通过医院官方渠道预约挂号，并在就诊当天提早到达，以便完成签到和候诊。 如需了解具体科室的出诊时间或医生排班，也可以告诉我，我会尽力帮您查询 😊 | I18: 正确 | J18: 1 | K18: 0 | L18: 2 | O18: =IF(N18="正确",1,IF(N18="部分正确",0.5,IF(N18="错误",0,"")))
A19: QA-018 | B19: 医院下午门诊到几点结束？ | C19: 医院信息 | D19: 下午门诊结束时间 | E19: 医院信息.md | F19: 900018 | G19: 北京协和医院下午门诊一般到 **17:00** 结束。不过具体科室可能略有不同，建议您提前预约并确认所就诊科室的出诊时间，以免耽误就诊。 如有其他问题，比如挂号、科室推荐等，也欢迎随时告诉我！😊 | I19: 正确 | J19: 1 | K19: 0 | L19: 1 | O19: =IF(N19="正确",1,IF(N19="部分正确",0.5,IF(N19="错误",0,"")))
A20: QA-019 | B20: 医院周末有门诊吗？ | C20: 医院信息 | D20: 是否开诊；周末安排 | E20: 医院信息.md | F20: 900019 | G20: 您好！我是“硅谷小智”，北京协和医院的智能客服，很高兴为您服务 😊 北京协和医院**周末是有门诊的**，但并非所有科室都开放。一般来说： - **周六上午**：多数科室（如内科、外科、妇产科、儿科等）会安排部分专家或普通门诊； - **周六下午及周日**：门诊科室较少，通常只开放急诊或个别重点专科。 建议您提前通过医院官网、官方App或电话查询具体科室的出诊安排，以免跑空。 如果您有想挂的具体科室或医生，也可以告诉我，我可以帮您查询是否有号源或协助预约～ | I20: 正确 | J20: 1 | K20: 0 | L20: 2 | O20: =IF(N20="正确",1,IF(N20="部分正确",0.5,IF(N20="错误",0,"")))
A21: QA-020 | B21: 医院节假日可以挂号吗？ | C21: 医院信息 | D21: 节假日门诊安排 | E21: 医院信息.md | F21: 900020 | G21: 您好！北京协和医院在节假日通常也会开放部分门诊，但具体是否可以挂号、哪些科室开诊，会根据国家法定节假日安排和医院实际排班有所调整。 建议您： - 在节假日期间如需就诊，可提前通过医院官网、“北京协和医院”App 或微信公众号查询当日出诊信息； - 部分科室（如急诊）全年无休，普通门诊和专科门诊可能轮休； - 节假日号源一般会提前放出，热门科室建议尽早预约。 如果您有具体想挂的科室或日期，我可以帮您查询是否有号源 😊 | I21: 正确 | J21: 1 | K21: 0 | L21: 1 | O21: =IF(N21="正确",1,IF(N21="部分正确",0.5,IF(N21="错误",0,"")))
A22: QA-021 | B22: 医院的联系电话是多少？ | C22: 医院信息 | D22: 联系电话 | E22: 医院信息.md | F22: 900021 | G22: 您好！北京协和医院的服务热线如下： - **东单院区**：010-69151188 地址：北京市东城区帅府园一号（邮编：100730） - **西单院区**：010-69158100 地址：北京市西城区大木仓胡同41号（邮编：100032） 📞 门诊时间：工作日 8:00–17:30 🚑 急诊：24小时开放 如有其他就诊或挂号相关问题，我也很乐意为您协助！😊 | I22: 正确 | J22: 1 | K22: 0 | L22: 1 | O22: =IF(N22="正确",1,IF(N22="部分正确",0.5,IF(N22="错误",0,"")))
A23: QA-022 | B23: 医院支持线上预约吗？ | C23: 医院信息 | D23: 是否支持；预约方式 | E23: 医院信息.md | F23: 900022 | G23: 您好！我是“硅谷小智”，北京协和医院的智能客服，很高兴为您服务！😊 是的，北京协和医院支持线上预约挂号。您可以通过我院官方渠道（如官网、官方App或微信公众号）进行预约，也可以在这里告诉我您的就诊需求，我会协助您完成预约流程。 如果您已有明确的科室、就诊日期和时间，也可以直接告诉我，我来帮您查询号源并安排预约。需要试试看吗？ | I23: 正确 | J23: 1 | K23: 0 | L23: 2 | O23: =IF(N23="正确",1,IF(N23="部分正确",0.5,IF(N23="错误",0,"")))
A24: QA-023 | B24: 第一次去医院就诊需要带什么？ | C24: 医院信息 | D24: 身份证；医保卡；就诊信息 | E24: 医院信息.md | F24: 900023 | G24: 您好！欢迎来到北京协和医院，我是您的智能客服“硅谷小智”😊。 第一次来院就诊，建议您携带以下材料，以便顺利挂号和就诊： 1. **有效身份证件**：如身份证、护照等（用于实名制挂号）； 2. **医保卡**（如有）：包括北京医保卡或异地医保备案凭证； 3. **既往病历资料**：如检查报告、化验单、影像片子（X光、CT、MRI等）、出院小结等； 4. **正在服用的药物清单**：有助于医生了解您的用药情况； 5. **联系方式准确的手机号**：用于接收预约、取号、检查结果等通知。 如果您已经在网上预约挂号，请记得在就诊当天**提前到院取号**（可通过自助机或窗口）。 如有其他问题，比如想预约挂号或查询科室信息，也欢迎随时告诉我！ | I24: 正确 | J24: 1 | K24: 2 | L24: 3 | M24: 身份证；医保卡 | O24: =IF(N24="正确",1,IF(N24="部分正确",0.5,IF(N24="错误",0,"")))
A25: QA-024 | B25: 医院有没有急诊？ | C25: 医院信息 | D25: 是否有急诊；位置或时间 | E25: 医院信息.md | F25: 900024 | G25: 有的，北京协和医院设有24小时急诊服务。🏥 如果您或他人出现急症、突发严重症状（如胸痛、呼吸困难、意识不清、大出血等），建议立即前往急诊科就诊，或拨打120寻求急救帮助。 如有其他就诊相关问题，也欢迎随时咨询我！ | I25: 正确 | J25: 1 | K25: 0 | L25: 2 | O25: =IF(N25="正确",1,IF(N25="部分正确",0.5,IF(N25="错误",0,"")))
A26: QA-025 | B26: 医院停车方便吗？ | C26: 医院信息 | D26: 停车场信息；停车说明 | E26: 医院信息.md | F26: 900025 | G26: 您好！我是“硅谷小智”，北京协和医院的智能客服 🌟 关于您的问题：协和医院地处北京市中心，周边交通较为繁忙，院内停车位有限，高峰时段（尤其是上午就诊高峰）停车可能比较紧张。建议您尽量选择公共交通前往。如确需驾车，可考虑周边公共停车场或合作停车点，部分院区也提供预约停车服务。 如果您需要了解具体院区（如东单院区、西单院区等）的停车详情，我可以进一步为您说明～ | I26: 正确 | J26: 1 | K26: 0 | L26: 2 | O26: =IF(N26="正确",1,IF(N26="部分正确",0.5,IF(N26="错误",0,"")))
A27: QA-026 | B27: 神经内科主要看哪些问题？ | C27: 科室信息 | D27: 头痛；头晕；脑血管疾病等 | E27: 神经内科.md | F27: 900026 | G27: 您好！我是“硅谷小智”，北京协和医院的智能客服，很高兴为您服务！😊 北京协和医院神经内科主要诊治以下几类疾病： - **脑血管病**：如脑梗死、脑出血、短暂性脑缺血发作（TIA）等； - **癫痫与发作性疾病**； - **帕金森病及其他运动障碍疾病**（如肌张力障碍、震颤等）； - **痴呆与认知功能障碍**（如阿尔茨海默病）； - **周围神经病与肌肉疾病**（如吉兰-巴雷综合征、重症肌无力等）； - **中枢神经系统感染与炎症**（如脑炎、多发性硬化等）； - **头痛与头晕**（包括偏头痛、紧张型头痛、眩晕等）； - **睡眠障碍与神经心理相关问题**。 如果您有上述相关症状，建议尽早就诊神经内科。部分疾病需结合影像学（如头颅MRI/CT）或电生理检查（如脑电图、肌电图）进一步明确诊断。 需要我帮您查询神经内科的号源或预约挂号吗？ | I27: 正确 | J27: 1 | K27: 2 | L27: 3 | M27: 头痛；头晕 | O27: =IF(N27="正确",1,IF(N27="部分正确",0.5,IF(N27="错误",0,"")))
A28: QA-027 | B28: 消化内科主要看什么病？ | C28: 科室信息 | D28: 胃痛；腹泻；消化系统疾病 | E28: 科室信息.md | F28: 900027 | G28: 消化内科主要诊治与消化系统相关的疾病，包括但不限于以下几类： - **食管疾病**：如胃食管反流病、食管炎、食管溃疡等 - **胃部疾病**：如胃炎、胃溃疡、功能性消化不良、幽门螺杆菌感染等 - **肠道疾病**：如肠易激综合征、炎症性肠病（克罗恩病、溃疡性结肠炎）、慢性腹泻或便秘等 - **肝胆胰疾病**：如脂肪肝、病毒性肝炎、肝硬化、胆囊炎、胆结石、胰腺炎等 - **其他**：不明原因的腹痛、腹胀、恶心、呕吐、黑便、消瘦等症状的排查 如果您有相关症状，建议尽早到消化内科就诊，必要时可能需要做胃镜、肠镜、腹部超声或血液检查等进一步评估。是否需要帮您预约挂号？😊 | I28: 正确 | J28: 1 | K28: 1 | L28: 3 | M28: 腹泻 | O28: =IF(N28="正确",1,IF(N28="部分正确",0.5,IF(N28="错误",0,"")))
A29: QA-028 | B29: 呼吸内科主要诊治哪些症状？ | C29: 科室信息 | D29: 咳嗽；气喘；肺部相关问题 | E29: 科室信息.md | F29: 900028 | G29: 呼吸内科主要诊治与呼吸系统相关的疾病和症状，常见的包括： - 咳嗽（急性或慢性） - 咳痰、咯血 - 呼吸困难、气短 - 胸痛（与呼吸相关） - 哮喘、慢性阻塞性肺疾病（COPD） - 肺炎、支气管炎、肺结核等感染性疾病 - 间质性肺病、肺栓塞 - 睡眠呼吸暂停综合征 - 肺部结节或肿瘤的初步评估 如果您有上述症状持续不缓解，建议尽早就诊呼吸内科，必要时进行胸部影像学（如胸片或CT）、肺功能等检查。需要我帮您预约呼吸内科的号源吗？🩺 | I29: 正确 | J29: 1 | K29: 1 | L29: 3 | M29: 咳嗽 | O29: =IF(N29="正确",1,IF(N29="部分正确",0.5,IF(N29="错误",0,"")))
A30: QA-029 | B30: 心内科主要看什么？ | C30: 科室信息 | D30: 胸闷；胸痛；心律失常等 | E30: 科室信息.md | F30: 900029 | G30: 心内科（心血管内科）主要诊治与心脏和血管相关的疾病，常见包括： - 高血压 - 冠心病（如心绞痛、心肌梗死） - 心律失常（心跳过快、过慢或不规则） - 心力衰竭 - 心肌炎、心包炎 - 心脏瓣膜病 - 血脂异常（高胆固醇等） - 动脉粥样硬化 如果您有胸闷、胸痛、心悸、气短、头晕等相关症状，建议及时到心内科就诊。是否需要我帮您查询心内科的号源或预约挂号？🫀 | I30: 正确 | J30: 1 | K30: 2 | L30: 3 | M30: 胸闷；胸痛 | O30: =IF(N30="正确",1,IF(N30="部分正确",0.5,IF(N30="错误",0,"")))
A31: QA-030 | B31: 骨科通常治疗哪些问题？ | C31: 科室信息 | D31: 骨折；关节痛；腰腿痛 | E31: 科室信息.md | F31: 900030 | G31: 骨科主要诊治与骨骼、关节、肌肉、韧带、肌腱、神经等相关的问题，常见的包括： - **骨折、脱位**：如手臂、腿、脊柱等部位的骨折或关节脱位 - **关节疾病**：如骨关节炎、类风湿性关节炎、肩周炎等 - **脊柱问题**：如颈椎病、腰椎间盘突出、脊柱侧弯等 - **运动损伤**：如韧带撕裂（如前交叉韧带）、半月板损伤、跟腱断裂等 - **骨质疏松**及其引发的疼痛或骨折 - **先天或后天畸形**：如扁平足、拇外翻、O型腿/X型腿等 - **骨肿瘤或软组织肿瘤**（部分需联合其他科室） 如果您有具体症状或不适，建议尽早就诊骨科进行专业评估。是否需要我帮您查询北京协和医院骨科的号源或预约挂号？🩺 | I31: 正确 | J31: 1 | K31: 1 | L31: 3 | M31: 骨折 | O31: =IF(N31="正确",1,IF(N31="部分正确",0.5,IF(N31="错误",0,"")))
A32: QA-031 | B32: 眼科主要处理哪些情况？ | C32: 科室信息 | D32: 视力下降；眼痛；眼部炎症 | E32: 科室信息.md | F32: 900031 | G32: 眼科主要负责诊断和治疗与眼睛及视觉系统相关的各类疾病和问题，常见包括： - **视力问题**：如近视、远视、散光、老花眼等 - **眼部炎症**：如结膜炎（红眼病）、角膜炎、睑缘炎等 - **眼底疾病**：如糖尿病视网膜病变、黄斑变性、视网膜脱落等 - **青光眼与白内障**：这两种是中老年人常见致盲性眼病 - **干眼症、视疲劳**：尤其在长时间使用电子屏幕人群中高发 - **斜视、弱视**：多见于儿童，需早期干预 - **眼外伤**：如异物入眼、化学灼伤、钝挫伤等 - **眼部肿瘤或先天异常**：较少见但需专业评估 如果您或家人出现视力下降、眼红、眼痛、流泪、视物变形等症状，建议尽早就诊眼科。需要我帮您预约眼科门诊吗？👀 | I32: 正确 | J32: 1 | K32: 3 | L32: 3 | M32: 视力下降；眼痛；眼部炎症 | O32: =IF(N32="正确",1,IF(N32="部分正确",0.5,IF(N32="错误",0,"")))
A33: QA-032 | B33: 耳鼻喉科看哪些病？ | C33: 科室信息 | D33: 耳鸣；鼻炎；咽喉不适 | E33: 科室信息.md | F33: 900032 | G33: 耳鼻喉科（也称“耳鼻咽喉头颈外科”）主要诊治以下几类疾病： 👂 **耳部疾病** - 中耳炎、外耳道炎 - 耳鸣、耳聋、听力下降 - 耳眩晕（如梅尼埃病） - 耳部异物、耳外伤 👃 **鼻部疾病** - 鼻炎（过敏性、慢性等） - 鼻窦炎、鼻息肉 - 鼻出血、鼻中隔偏曲 - 嗅觉障碍 🫁 **咽喉及头颈疾病** - 咽炎、扁桃体炎 - 声音嘶哑、声带息肉/结节 - 打鼾、睡眠呼吸暂停综合征 - 喉咙异物感、吞咽困难 - 甲状腺、颈部肿块等头颈部疾病 如果您有以上相关症状，建议及时就诊耳鼻喉科。需要我帮您查询号源或预约挂号吗？😊 | I33: 正确 | J33: 1 | K33: 2 | L33: 3 | M33: 耳鸣；鼻炎 | O33: =IF(N33="正确",1,IF(N33="部分正确",0.5,IF(N33="错误",0,"")))
A34: QA-033 | B34: 皮肤科主要看什么问题？ | C34: 科室信息 | D34: 过敏；湿疹；皮疹等 | E34: 科室信息.md | F34: 900033 | G34: 皮肤科主要诊治与皮肤、毛发、指甲及相关黏膜相关的各类疾病，常见的包括： - **皮肤炎症**：如湿疹、皮炎、接触性皮炎等 - **感染性疾病**：如真菌感染（脚气、体癣）、细菌感染（毛囊炎）、病毒感染（带状疱疹、疣）等 - **过敏性疾病**：如荨麻疹、药疹、过敏性皮炎等 - **痤疮与青春痘** - **色素性疾病**：如白癜风、黄褐斑、雀斑等 - **皮肤肿瘤**：良性（如痣、脂溢性角化）或可疑恶性病变（如黑色素瘤） - **脱发与头皮问题** - **甲病**：如灰指甲、甲沟炎等 如果您有具体症状，也可以告诉我，我可以帮您初步判断是否需要就诊皮肤科 😊。必要时建议尽早就医，由专业医生面诊评估。 | I34: 正确 | J34: 1 | K34: 2 | L34: 3 | M34: 过敏；湿疹 | O34: =IF(N34="正确",1,IF(N34="部分正确",0.5,IF(N34="错误",0,"")))
A35: QA-034 | B35: 儿科可以看哪些常见病？ | C35: 科室信息 | D35: 发热；咳嗽；腹泻等儿童常见病 | E35: 科室信息.md | F35: 900034 | G35: 您好！我是“硅谷小智”，北京协和医院的智能客服，很高兴为您服务。😊 儿科主要诊治0～18岁儿童的各类常见病和多发病，包括但不限于以下几类： - **呼吸系统疾病**：如感冒、咳嗽、支气管炎、肺炎、哮喘等 - **消化系统疾病**：如腹泻、呕吐、腹痛、便秘、消化不良等 - **感染性疾病**：如手足口病、水痘、麻疹、流感、疱疹性咽峡炎等 - **过敏性疾病**：如湿疹、荨麻疹、过敏性鼻炎等 - **生长发育问题**：如营养不良、肥胖、矮小症、性早熟等 - **其他常见问题**：发热、皮疹、睡眠障碍、喂养困难等 ⚠️ 温馨提示：如果孩子症状较重（如持续高热、呼吸困难、精神差、脱水等），建议尽快线下就诊，以免延误病情。 如果您需要为孩子预约儿科门诊，也可以告诉我具体需求，我可以帮您查询号源或安排挂号。 | I35: 正确 | J35: 1 | K35: 2 | L35: 3 | M35: 发热；咳嗽 | O35: =IF(N35="正确",1,IF(N35="部分正确",0.5,IF(N35="错误",0,"")))
A36: QA-035 | B36: 口腔科一般能处理哪些问题？ | C36: 科室信息 | D36: 牙痛；蛀牙；口腔检查 | E36: 口腔科.md | F36: 900035 | G36: 您好！我是硅谷小智，北京协和医院的智能客服😊 很高兴为您服务！ 口腔科主要处理以下常见问题： - **牙体牙髓疾病**：如龋齿（蛀牙）、牙痛、牙髓炎、根尖周炎等 - **牙周疾病**：如牙龈出血、牙周炎、牙龈萎缩等 - **口腔黏膜病**：如口腔溃疡、扁平苔藓、白斑等 - **牙齿拔除**：包括智齿、残根、松动牙等的拔牙手术 - **牙齿修复**：如补牙、嵌体、全冠、活动/固定假牙等 - **牙齿矫正**（部分医院由正畸专科负责） - **口腔颌面部小手术**：如囊肿切除、小肿物处理等 - **儿童口腔问题**：乳牙护理、窝沟封闭、早期矫治等 如果您有具体症状或不确定是否属于口腔科范畴，也可以告诉我，我会帮您初步判断是否需要就诊以及挂哪个细分方向的号哦！🦷 | I36: 正确 | J36: 1 | K36: 2 | L36: 3 | M36: 牙痛；蛀牙 | O36: =IF(N36="正确",1,IF(N36="部分正确",0.5,IF(N36="错误",0,"")))
A37: QA-036 | B37: 怎么预约挂号？ | C37: 流程咨询 | D37: 线上/线下预约方式；所需信息 | E37: 医院信息.md | F37: 900036 | G37: 您好！我是“硅谷小智”，北京协和医院的智能客服，很高兴为您服务！😊 预约挂号需要提供以下信息： 1. **您的姓名** 2. **身份证号** 3. **想挂的科室名称**（如：心血管内科、皮肤科等） 4. **就诊日期**（格式如：2026-03-15） 5. **时间段**（上午 或 下午） 6. **医生姓名**（可选，若未指定，我可以为您推荐） 请您先告诉我您想挂哪个科室？以及希望就诊的日期和时间段？我会帮您查询是否有号源，并一步步协助完成预约。 | I37: 正确 | J37: 1 | K37: 0 | L37: 2 | O37: =IF(N37="正确",1,IF(N37="部分正确",0.5,IF(N37="错误",0,"")))
A38: QA-037 | B38: 预约挂号需要提前多久？ | C38: 流程咨询 | D38: 预约时间要求；规则说明 | E38: 医院信息.md | F38: 900037 | G38: 您好！在北京协和医院，预约挂号一般可提前 **7天** 预约（不含当日）。也就是说，今天是2026年3月11日，您最早可以预约到 **2026年3月18日** 的号源。 ⏰ 放号时间通常为每日 **下午4点** 更新第7天的号源，建议您在放号后尽早操作，热门科室或专家号可能很快约满。 如果您已有明确的就诊需求（如科室、日期等），我可以帮您查询是否有号源或协助预约～ 😊 | I38: 正确 | J38: 1 | K38: 0 | L38: 2 | O38: =IF(N38="正确",1,IF(N38="部分正确",0.5,IF(N38="错误",0,"")))
A39: QA-038 | B39: 挂号后还能取消吗？ | C39: 流程咨询 | D39: 可以取消；取消规则 | E39: 医院信息.md | F39: 900038 | G39: 您好！挂号成功后是可以取消的，但需要在就诊日期之前操作。如果您是通过北京协和医院官方渠道（如App、官网或微信公众号）预约的号源，一般在就诊前一日24:00前可以免费取消；逾期未取消可能视为爽约，影响后续预约。 如您现在就需要取消某次预约，请提供以下信息，我可以帮您操作： - 姓名 - 身份证号 - 预约的科室 - 就诊日期（格式如：2026-03-15） - 就诊时间（上午 / 下午） - 医生姓名（如记得） 请放心，我会先核对预约记录，确认后再为您取消。😊 | I39: 正确 | J39: 1 | K39: 1 | L39: 2 | M39: 可以取消 | O39: =IF(N39="正确",1,IF(N39="部分正确",0.5,IF(N39="错误",0,"")))
A40: QA-039 | B40: 取消预约要怎么操作？ | C40: 流程咨询 | D40: 取消入口；取消方式 | E40: 医院信息.md | F40: 900039 | G40: 您好！我是“硅谷小智”，北京协和医院的智能客服，很高兴为您服务。😊 要取消预约挂号，请您提供以下信息，以便我们为您核实并操作： 1. **您的姓名** 2. **身份证号** 3. **原预约的科室名称** 4. **预约日期**（例如：2026-03-15） 5. **预约时段**（上午 / 下午） 6. **医生姓名**（如记得的话，可选） 请您先提供上述信息中的**姓名和身份证号**，我将帮您查询相关预约记录。 | I40: 正确 | J40: 1 | K40: 0 | L40: 2 | O40: =IF(N40="正确",1,IF(N40="部分正确",0.5,IF(N40="错误",0,"")))
...
